[Extracted question from page 1]
No questions found.
[End of extracted question from page 1]

[Extracted question from page 2]
1.  
(a) Let \( k \) be a constant. Express  
\[ \lim_{h \to 0} \frac{e^{-kh - h^2} - 1}{h} \]  
in terms of \( k \).  
(b) Let \( f(x) = xe^{-x^2} \). Using the result of (a), find \( f'(x) \) from first principles.
[End of extracted question from page 2]

[Extracted question from page 3]
2. By considering the function \( f(x) = xe^{-x} \), show that \( a e^{b} \geq b e^{a} \) if \( 1 \leq a < b \).
(4 marks)
[End of extracted question from page 3]

[Extracted question from page 4]
3. Let $n$ be an integer greater than 1. Define $(x - a)^n = \sum_{k=0}^{n} \mu_k x^k$, where $a$ is an integral constant. It is given that $\frac{\mu_2}{\mu_1} = -\frac{4}{3}$.
(a) Chungchung claims that $n$ is an odd number and $a > 0$. Do you agree? Explain your answer.
(b) Let $(bx - 6)^{2n} = \sum_{k=0}^{2n} \lambda_k x^{2n-k}$, where $b$ is an integral constant. If $\lambda_0 = \mu_n$ and $\lambda_1 = -4\mu_{n-1}$, find $a$, $b$ and $n$.
[End of extracted question from page 4]

[Extracted question from page 5]
(a) Prove that $\sin \pi x^{2} + \sin 2\pi x - \sin \pi (x^{2} + 2x) = \frac{4 \sin \pi (x^{2} + 2x)}{2} \sin \frac{\pi x}{2} \sin \pi x$.
(b) Find the least positive value of $x$ such that $\sin \pi x^{2} + \sin 2\pi x = \sin \pi (x^{2} + 2x)$.
[End of extracted question from page 5]

[Extracted question from page 6]
No questions found.
[End of extracted question from page 6]

[Extracted question from page 7]
5. Consider the curve Γ : \( y = e^{-2x} \), where \( x \geq 0 \). Let P be a moving point on Γ with \( h \) as its x−coordinate, where \( h > 0 \). Denote the tangent to Γ at P by L and the area of the region bounded by Γ , L and the y-axis by A .
(a) Prove that \( A = e^{-2h} \left( e^{2h} - 2h^{2} - 2h - 1 \right) \).

(b) If \( h = \ln (t + 1) \), where \( t \) is the time, find the rate of change of A when \( t = 2 \).
[End of extracted question from page 7]

[Extracted question from page 8]
Internal Server Error: /upload_file
Traceback (most recent call last):
  File "/home/udontur/code/ai-mock/.venv/lib/python3.12/site-packages/django/core/handlers/exception.py", line 55, in inner
    response = get_response(request)
               ^^^^^^^^^^^^^^^^^^^^^
  File "/home/udontur/code/ai-mock/.venv/lib/python3.12/site-packages/django/core/handlers/base.py", line 197, in _get_response
    response = wrapped_callback(request, *callback_args, **callback_kwargs)
               ^^^^^^^^^^^^^^^^^^^^^^^^^^^^^^^^^^^^^^^^^^^^^^^^^^^^^^^^^^^^
  File "/home/udontur/code/ai-mock/app/views.py", line 54, in upload_file
    text = read_file(uploaded_file)
           ^^^^^^^^^^^^^^^^^^^^^^^^
  File "/home/udontur/code/ai-mock/app/views.py", line 14, in read_file
    extracted_questions=parse_text(current_page_text).content
                        ^^^^^^^^^^^^^^^^^^^^^^^^^^^^^
  File "/home/udontur/code/ai-mock/app/views.py", line 43, in parse_text
    response = llm_chain.invoke(input={'text': text})
               ^^^^^^^^^^^^^^^^^^^^^^^^^^^^^^^^^^^^^^
  File "/home/udontur/code/ai-mock/.venv/lib/python3.12/site-packages/langchain_core/runnables/base.py", line 3047, in invoke
    input_ = context.run(step.invoke, input_, config)
             ^^^^^^^^^^^^^^^^^^^^^^^^^^^^^^^^^^^^^^^^
  File "/home/udontur/code/ai-mock/.venv/lib/python3.12/site-packages/langchain_core/language_models/chat_models.py", line 378, in invoke
    self.generate_prompt(
  File "/home/udontur/code/ai-mock/.venv/lib/python3.12/site-packages/langchain_core/language_models/chat_models.py", line 963, in generate_prompt
    return self.generate(prompt_messages, stop=stop, callbacks=callbacks, **kwargs)
           ^^^^^^^^^^^^^^^^^^^^^^^^^^^^^^^^^^^^^^^^^^^^^^^^^^^^^^^^^^^^^^^^^^^^^^^^
  File "/home/udontur/code/ai-mock/.venv/lib/python3.12/site-packages/langchain_core/language_models/chat_models.py", line 782, in generate
    self._generate_with_cache(
  File "/home/udontur/code/ai-mock/.venv/lib/python3.12/site-packages/langchain_core/language_models/chat_models.py", line 1028, in _generate_with_cache
    result = self._generate(
             ^^^^^^^^^^^^^^^
  File "/home/udontur/code/ai-mock/.venv/lib/python3.12/site-packages/langchain_openai/chat_models/base.py", line 1131, in _generate
    return self._create_chat_result(response, generation_info)
           ^^^^^^^^^^^^^^^^^^^^^^^^^^^^^^^^^^^^^^^^^^^^^^^^^^^
  File "/home/udontur/code/ai-mock/.venv/lib/python3.12/site-packages/langchain_openai/chat_models/base.py", line 1188, in _create_chat_result
    raise ValueError(response_dict.get("error"))
ValueError: {'message': 'Internal Server Error', 'code': 500}
[14/Jul/2025 09:00:54] "POST /upload_file HTTP/1.1" 500 159290
